[2024-04-17T04:22:56.240+0000] {local_task_job_runner.py:120} INFO - ::group::Pre task execution logs
[2024-04-17T04:22:56.271+0000] {taskinstance.py:2073} INFO - Dependencies all met for dep_context=non-requeueable deps ti=<TaskInstance: dagExtract.validateData scheduled__2024-04-17T02:30:00+00:00 [queued]>
[2024-04-17T04:22:56.282+0000] {taskinstance.py:2073} INFO - Dependencies all met for dep_context=requeueable deps ti=<TaskInstance: dagExtract.validateData scheduled__2024-04-17T02:30:00+00:00 [queued]>
[2024-04-17T04:22:56.283+0000] {taskinstance.py:2303} INFO - Starting attempt 2 of 2
[2024-04-17T04:22:56.308+0000] {taskinstance.py:2327} INFO - Executing <Task(BranchPythonOperator): validateData> on 2024-04-17 02:30:00+00:00
[2024-04-17T04:22:56.317+0000] {warnings.py:110} WARNING - /home/***/.local/lib/python3.12/site-packages/***/task/task_runner/standard_task_runner.py:61: DeprecationWarning: This process (pid=198) is multi-threaded, use of fork() may lead to deadlocks in the child.
  pid = os.fork()

[2024-04-17T04:22:56.319+0000] {standard_task_runner.py:90} INFO - Running: ['***', 'tasks', 'run', 'dagExtract', 'validateData', 'scheduled__2024-04-17T02:30:00+00:00', '--job-id', '95', '--raw', '--subdir', 'DAGS_FOLDER/FirstDag.py', '--cfg-path', '/tmp/tmp_nikloel']
[2024-04-17T04:22:56.321+0000] {standard_task_runner.py:63} INFO - Started process 200 to run task
[2024-04-17T04:22:56.321+0000] {standard_task_runner.py:91} INFO - Job 95: Subtask validateData
[2024-04-17T04:22:56.404+0000] {task_command.py:426} INFO - Running <TaskInstance: dagExtract.validateData scheduled__2024-04-17T02:30:00+00:00 [running]> on host 960ed0fb8e64
[2024-04-17T04:22:56.546+0000] {taskinstance.py:2644} INFO - Exporting env vars: AIRFLOW_CTX_DAG_OWNER='***' AIRFLOW_CTX_DAG_ID='dagExtract' AIRFLOW_CTX_TASK_ID='validateData' AIRFLOW_CTX_EXECUTION_DATE='2024-04-17T02:30:00+00:00' AIRFLOW_CTX_TRY_NUMBER='2' AIRFLOW_CTX_DAG_RUN_ID='scheduled__2024-04-17T02:30:00+00:00'
[2024-04-17T04:22:56.548+0000] {taskinstance.py:430} INFO - ::endgroup::
[2024-04-17T04:22:56.549+0000] {baseoperator.py:399} WARNING - BranchPythonOperator.execute cannot be called outside TaskInstance!
[2024-04-17T04:22:56.658+0000] {taskinstance.py:441} INFO - ::group::Post task execution logs
[2024-04-17T04:22:56.660+0000] {taskinstance.py:2890} ERROR - Task failed with exception
Traceback (most recent call last):
  File "/home/airflow/.local/lib/python3.12/site-packages/airflow/models/taskinstance.py", line 465, in _execute_task
    result = _execute_callable(context=context, **execute_callable_kwargs)
             ^^^^^^^^^^^^^^^^^^^^^^^^^^^^^^^^^^^^^^^^^^^^^^^^^^^^^^^^^^^^^
  File "/home/airflow/.local/lib/python3.12/site-packages/airflow/models/taskinstance.py", line 432, in _execute_callable
    return execute_callable(context=context, **execute_callable_kwargs)
           ^^^^^^^^^^^^^^^^^^^^^^^^^^^^^^^^^^^^^^^^^^^^^^^^^^^^^^^^^^^^
  File "/home/airflow/.local/lib/python3.12/site-packages/airflow/models/baseoperator.py", line 400, in wrapper
    return func(self, *args, **kwargs)
           ^^^^^^^^^^^^^^^^^^^^^^^^^^^
  File "/home/airflow/.local/lib/python3.12/site-packages/airflow/operators/python.py", line 269, in execute
    return self.do_branch(context, super().execute(context))
                                   ^^^^^^^^^^^^^^^^^^^^^^^^
  File "/home/airflow/.local/lib/python3.12/site-packages/airflow/models/baseoperator.py", line 400, in wrapper
    return func(self, *args, **kwargs)
           ^^^^^^^^^^^^^^^^^^^^^^^^^^^
  File "/home/airflow/.local/lib/python3.12/site-packages/airflow/operators/python.py", line 235, in execute
    return_value = self.execute_callable()
                   ^^^^^^^^^^^^^^^^^^^^^^^
  File "/home/airflow/.local/lib/python3.12/site-packages/airflow/operators/python.py", line 252, in execute_callable
    return self.python_callable(*self.op_args, **self.op_kwargs)
           ^^^^^^^^^^^^^^^^^^^^^^^^^^^^^^^^^^^^^^^^^^^^^^^^^^^^^
  File "/opt/airflow/dags/FirstDag.py", line 24, in ValidateData
    print("Df Size: " + size)
          ~~~~~~~~~~~~^~~~~~
TypeError: can only concatenate str (not "int") to str
[2024-04-17T04:22:56.680+0000] {taskinstance.py:1205} INFO - Marking task as FAILED. dag_id=dagExtract, task_id=validateData, execution_date=20240417T023000, start_date=20240417T042256, end_date=20240417T042256
[2024-04-17T04:22:56.703+0000] {standard_task_runner.py:110} ERROR - Failed to execute job 95 for task validateData (can only concatenate str (not "int") to str; 200)
[2024-04-17T04:22:56.738+0000] {local_task_job_runner.py:240} INFO - Task exited with return code 1
[2024-04-17T04:22:56.797+0000] {taskinstance.py:3482} INFO - 0 downstream tasks scheduled from follow-on schedule check
[2024-04-17T04:22:56.807+0000] {local_task_job_runner.py:222} INFO - ::endgroup::
