[2024-04-17T22:42:39.609+0000] {local_task_job_runner.py:120} INFO - ::group::Pre task execution logs
[2024-04-17T22:42:39.639+0000] {taskinstance.py:2073} INFO - Dependencies all met for dep_context=non-requeueable deps ti=<TaskInstance: dagPartition.partition scheduled__2024-04-17T21:30:00+00:00 [queued]>
[2024-04-17T22:42:39.649+0000] {taskinstance.py:2073} INFO - Dependencies all met for dep_context=requeueable deps ti=<TaskInstance: dagPartition.partition scheduled__2024-04-17T21:30:00+00:00 [queued]>
[2024-04-17T22:42:39.650+0000] {taskinstance.py:2303} INFO - Starting attempt 1 of 1
[2024-04-17T22:42:39.669+0000] {taskinstance.py:2327} INFO - Executing <Task(PythonOperator): partition> on 2024-04-17 21:30:00+00:00
[2024-04-17T22:42:39.679+0000] {warnings.py:110} WARNING - /home/***/.local/lib/python3.12/site-packages/***/task/task_runner/standard_task_runner.py:61: DeprecationWarning: This process (pid=432) is multi-threaded, use of fork() may lead to deadlocks in the child.
  pid = os.fork()

[2024-04-17T22:42:39.682+0000] {standard_task_runner.py:63} INFO - Started process 434 to run task
[2024-04-17T22:42:39.681+0000] {standard_task_runner.py:90} INFO - Running: ['***', 'tasks', 'run', 'dagPartition', 'partition', 'scheduled__2024-04-17T21:30:00+00:00', '--job-id', '118', '--raw', '--subdir', 'DAGS_FOLDER/PartitionLocation.py', '--cfg-path', '/tmp/tmp17and2ui']
[2024-04-17T22:42:39.683+0000] {standard_task_runner.py:91} INFO - Job 118: Subtask partition
[2024-04-17T22:42:39.749+0000] {task_command.py:426} INFO - Running <TaskInstance: dagPartition.partition scheduled__2024-04-17T21:30:00+00:00 [running]> on host 0761b779d565
[2024-04-17T22:42:39.884+0000] {taskinstance.py:2644} INFO - Exporting env vars: AIRFLOW_CTX_DAG_OWNER='***' AIRFLOW_CTX_DAG_ID='dagPartition' AIRFLOW_CTX_TASK_ID='partition' AIRFLOW_CTX_EXECUTION_DATE='2024-04-17T21:30:00+00:00' AIRFLOW_CTX_TRY_NUMBER='1' AIRFLOW_CTX_DAG_RUN_ID='scheduled__2024-04-17T21:30:00+00:00'
[2024-04-17T22:42:39.886+0000] {taskinstance.py:430} INFO - ::endgroup::
[2024-04-17T22:42:39.888+0000] {taskinstance.py:441} INFO - ::group::Post task execution logs
[2024-04-17T22:42:39.889+0000] {taskinstance.py:2890} ERROR - Task failed with exception
Traceback (most recent call last):
  File "/home/airflow/.local/lib/python3.12/site-packages/airflow/models/taskinstance.py", line 465, in _execute_task
    result = _execute_callable(context=context, **execute_callable_kwargs)
             ^^^^^^^^^^^^^^^^^^^^^^^^^^^^^^^^^^^^^^^^^^^^^^^^^^^^^^^^^^^^^
  File "/home/airflow/.local/lib/python3.12/site-packages/airflow/models/taskinstance.py", line 432, in _execute_callable
    return execute_callable(context=context, **execute_callable_kwargs)
           ^^^^^^^^^^^^^^^^^^^^^^^^^^^^^^^^^^^^^^^^^^^^^^^^^^^^^^^^^^^^
  File "/home/airflow/.local/lib/python3.12/site-packages/airflow/models/baseoperator.py", line 400, in wrapper
    return func(self, *args, **kwargs)
           ^^^^^^^^^^^^^^^^^^^^^^^^^^^
  File "/home/airflow/.local/lib/python3.12/site-packages/airflow/operators/python.py", line 235, in execute
    return_value = self.execute_callable()
                   ^^^^^^^^^^^^^^^^^^^^^^^
  File "/home/airflow/.local/lib/python3.12/site-packages/airflow/operators/python.py", line 252, in execute_callable
    return self.python_callable(*self.op_args, **self.op_kwargs)
           ^^^^^^^^^^^^^^^^^^^^^^^^^^^^^^^^^^^^^^^^^^^^^^^^^^^^^
  File "/opt/airflow/dags/PartitionLocation.py", line 10, in ReadBronze
    df = pd.read_json('datalake/bronze/*.json')
         ^^^^^^^^^^^^^^^^^^^^^^^^^^^^^^^^^^^^^^
  File "/home/airflow/.local/lib/python3.12/site-packages/pandas/io/json/_json.py", line 780, in read_json
    json_reader = JsonReader(
                  ^^^^^^^^^^^
  File "/home/airflow/.local/lib/python3.12/site-packages/pandas/io/json/_json.py", line 893, in __init__
    data = self._get_data_from_filepath(filepath_or_buffer)
           ^^^^^^^^^^^^^^^^^^^^^^^^^^^^^^^^^^^^^^^^^^^^^^^^
  File "/home/airflow/.local/lib/python3.12/site-packages/pandas/io/json/_json.py", line 949, in _get_data_from_filepath
    raise FileNotFoundError(f"File {filepath_or_buffer} does not exist")
FileNotFoundError: File datalake/bronze/*.json does not exist
[2024-04-17T22:42:39.905+0000] {taskinstance.py:1205} INFO - Marking task as FAILED. dag_id=dagPartition, task_id=partition, execution_date=20240417T213000, start_date=20240417T224239, end_date=20240417T224239
[2024-04-17T22:42:39.924+0000] {standard_task_runner.py:110} ERROR - Failed to execute job 118 for task partition (File datalake/bronze/*.json does not exist; 434)
[2024-04-17T22:42:39.977+0000] {local_task_job_runner.py:240} INFO - Task exited with return code 1
[2024-04-17T22:42:40.015+0000] {taskinstance.py:3482} INFO - 0 downstream tasks scheduled from follow-on schedule check
[2024-04-17T22:42:40.020+0000] {local_task_job_runner.py:222} INFO - ::endgroup::
