[2024-04-18T03:38:18.009+0000] {local_task_job_runner.py:120} INFO - ::group::Pre task execution logs
[2024-04-18T03:38:18.034+0000] {taskinstance.py:2073} INFO - Dependencies all met for dep_context=non-requeueable deps ti=<TaskInstance: dagAggregation.vwCountry scheduled__2024-04-18T01:30:00+00:00 [queued]>
[2024-04-18T03:38:18.043+0000] {taskinstance.py:2073} INFO - Dependencies all met for dep_context=requeueable deps ti=<TaskInstance: dagAggregation.vwCountry scheduled__2024-04-18T01:30:00+00:00 [queued]>
[2024-04-18T03:38:18.045+0000] {taskinstance.py:2303} INFO - Starting attempt 4 of 4
[2024-04-18T03:38:18.063+0000] {taskinstance.py:2327} INFO - Executing <Task(PythonOperator): vwCountry> on 2024-04-18 01:30:00+00:00
[2024-04-18T03:38:18.070+0000] {warnings.py:110} WARNING - /home/***/.local/lib/python3.12/site-packages/***/task/task_runner/standard_task_runner.py:61: DeprecationWarning: This process (pid=6269) is multi-threaded, use of fork() may lead to deadlocks in the child.
  pid = os.fork()

[2024-04-18T03:38:18.072+0000] {standard_task_runner.py:63} INFO - Started process 6271 to run task
[2024-04-18T03:38:18.072+0000] {standard_task_runner.py:90} INFO - Running: ['***', 'tasks', 'run', 'dagAggregation', 'vwCountry', 'scheduled__2024-04-18T01:30:00+00:00', '--job-id', '314', '--raw', '--subdir', 'DAGS_FOLDER/AggData.py', '--cfg-path', '/tmp/tmp_a6tev4l']
[2024-04-18T03:38:18.074+0000] {standard_task_runner.py:91} INFO - Job 314: Subtask vwCountry
[2024-04-18T03:38:18.168+0000] {task_command.py:426} INFO - Running <TaskInstance: dagAggregation.vwCountry scheduled__2024-04-18T01:30:00+00:00 [running]> on host 0761b779d565
[2024-04-18T03:38:18.305+0000] {taskinstance.py:2644} INFO - Exporting env vars: AIRFLOW_CTX_DAG_OWNER='***' AIRFLOW_CTX_DAG_ID='dagAggregation' AIRFLOW_CTX_TASK_ID='vwCountry' AIRFLOW_CTX_EXECUTION_DATE='2024-04-18T01:30:00+00:00' AIRFLOW_CTX_TRY_NUMBER='4' AIRFLOW_CTX_DAG_RUN_ID='scheduled__2024-04-18T01:30:00+00:00'
[2024-04-18T03:38:18.307+0000] {taskinstance.py:430} INFO - ::endgroup::
[2024-04-18T03:38:18.466+0000] {logging_mixin.py:188} INFO -                                       id  ...            city
21  fb94830f-6196-4f59-9189-c9060b778085  ...         Gilbert
21  fb94830f-6196-4f59-9189-c9060b778085  ...         Gilbert
22  0faa0fb2-fffa-416d-9eab-46f67477c8ef  ...            Mesa
22  0faa0fb2-fffa-416d-9eab-46f67477c8ef  ...            Mesa
49  4f4b5b34-d572-4dff-a18f-47e507c073e6  ...          Tucson
..                                   ...  ...             ...
12  03118499-a3d0-4c22-860d-4529509ae095  ...        Quilcene
44  1a1b2165-73ed-40aa-b89b-56794d140f22  ...       Milwaukee
44  1a1b2165-73ed-40aa-b89b-56794d140f22  ...       Milwaukee
2   34e8c68b-6146-453f-a4b9-1f6cd99a5ada  ...  Mount Pleasant
2   34e8c68b-6146-453f-a4b9-1f6cd99a5ada  ...  Mount Pleasant

[98 rows x 16 columns]
[2024-04-18T03:38:18.467+0000] {taskinstance.py:441} INFO - ::group::Post task execution logs
[2024-04-18T03:38:18.468+0000] {taskinstance.py:2890} ERROR - Task failed with exception
Traceback (most recent call last):
  File "/home/airflow/.local/lib/python3.12/site-packages/pandas/core/generic.py", line 552, in _get_axis_number
    return cls._AXIS_TO_AXIS_NUMBER[axis]
           ~~~~~~~~~~~~~~~~~~~~~~~~^^^^^^
KeyError: 'state'

During handling of the above exception, another exception occurred:

Traceback (most recent call last):
  File "/home/airflow/.local/lib/python3.12/site-packages/airflow/models/taskinstance.py", line 465, in _execute_task
    result = _execute_callable(context=context, **execute_callable_kwargs)
             ^^^^^^^^^^^^^^^^^^^^^^^^^^^^^^^^^^^^^^^^^^^^^^^^^^^^^^^^^^^^^
  File "/home/airflow/.local/lib/python3.12/site-packages/airflow/models/taskinstance.py", line 432, in _execute_callable
    return execute_callable(context=context, **execute_callable_kwargs)
           ^^^^^^^^^^^^^^^^^^^^^^^^^^^^^^^^^^^^^^^^^^^^^^^^^^^^^^^^^^^^
  File "/home/airflow/.local/lib/python3.12/site-packages/airflow/models/baseoperator.py", line 400, in wrapper
    return func(self, *args, **kwargs)
           ^^^^^^^^^^^^^^^^^^^^^^^^^^^
  File "/home/airflow/.local/lib/python3.12/site-packages/airflow/operators/python.py", line 235, in execute
    return_value = self.execute_callable()
                   ^^^^^^^^^^^^^^^^^^^^^^^
  File "/home/airflow/.local/lib/python3.12/site-packages/airflow/operators/python.py", line 252, in execute_callable
    return self.python_callable(*self.op_args, **self.op_kwargs)
           ^^^^^^^^^^^^^^^^^^^^^^^^^^^^^^^^^^^^^^^^^^^^^^^^^^^^^
  File "/opt/airflow/dags/AggData.py", line 48, in GroupByCountry
    vw_location = df.groupby('country', 'state', 'city')['id'].count().reset_index()
                  ^^^^^^^^^^^^^^^^^^^^^^^^^^^^^^^^^^^^^^
  File "/home/airflow/.local/lib/python3.12/site-packages/pandas/core/frame.py", line 8846, in groupby
    axis = self._get_axis_number(axis)
           ^^^^^^^^^^^^^^^^^^^^^^^^^^^
  File "/home/airflow/.local/lib/python3.12/site-packages/pandas/core/generic.py", line 554, in _get_axis_number
    raise ValueError(f"No axis named {axis} for object type {cls.__name__}")
ValueError: No axis named state for object type DataFrame
[2024-04-18T03:38:18.498+0000] {taskinstance.py:1205} INFO - Marking task as FAILED. dag_id=dagAggregation, task_id=vwCountry, execution_date=20240418T013000, start_date=20240418T033818, end_date=20240418T033818
[2024-04-18T03:38:18.525+0000] {standard_task_runner.py:110} ERROR - Failed to execute job 314 for task vwCountry (No axis named state for object type DataFrame; 6271)
[2024-04-18T03:38:18.569+0000] {local_task_job_runner.py:240} INFO - Task exited with return code 1
[2024-04-18T03:38:18.599+0000] {taskinstance.py:3482} INFO - 0 downstream tasks scheduled from follow-on schedule check
[2024-04-18T03:38:18.604+0000] {local_task_job_runner.py:222} INFO - ::endgroup::
