[2024-04-18T03:45:16.226+0000] {local_task_job_runner.py:120} INFO - ::group::Pre task execution logs
[2024-04-18T03:45:16.256+0000] {taskinstance.py:2073} INFO - Dependencies all met for dep_context=non-requeueable deps ti=<TaskInstance: dagAggregation.vwCountry scheduled__2024-04-18T01:30:00+00:00 [queued]>
[2024-04-18T03:45:16.266+0000] {taskinstance.py:2073} INFO - Dependencies all met for dep_context=requeueable deps ti=<TaskInstance: dagAggregation.vwCountry scheduled__2024-04-18T01:30:00+00:00 [queued]>
[2024-04-18T03:45:16.267+0000] {taskinstance.py:2303} INFO - Starting attempt 5 of 5
[2024-04-18T03:45:16.286+0000] {taskinstance.py:2327} INFO - Executing <Task(PythonOperator): vwCountry> on 2024-04-18 01:30:00+00:00
[2024-04-18T03:45:16.294+0000] {warnings.py:110} WARNING - /home/***/.local/lib/python3.12/site-packages/***/task/task_runner/standard_task_runner.py:61: DeprecationWarning: This process (pid=6395) is multi-threaded, use of fork() may lead to deadlocks in the child.
  pid = os.fork()

[2024-04-18T03:45:16.296+0000] {standard_task_runner.py:63} INFO - Started process 6397 to run task
[2024-04-18T03:45:16.296+0000] {standard_task_runner.py:90} INFO - Running: ['***', 'tasks', 'run', 'dagAggregation', 'vwCountry', 'scheduled__2024-04-18T01:30:00+00:00', '--job-id', '316', '--raw', '--subdir', 'DAGS_FOLDER/AggData.py', '--cfg-path', '/tmp/tmpn0iomed7']
[2024-04-18T03:45:16.298+0000] {standard_task_runner.py:91} INFO - Job 316: Subtask vwCountry
[2024-04-18T03:45:16.367+0000] {task_command.py:426} INFO - Running <TaskInstance: dagAggregation.vwCountry scheduled__2024-04-18T01:30:00+00:00 [running]> on host 0761b779d565
[2024-04-18T03:45:16.495+0000] {taskinstance.py:2644} INFO - Exporting env vars: AIRFLOW_CTX_DAG_OWNER='***' AIRFLOW_CTX_DAG_ID='dagAggregation' AIRFLOW_CTX_TASK_ID='vwCountry' AIRFLOW_CTX_EXECUTION_DATE='2024-04-18T01:30:00+00:00' AIRFLOW_CTX_TRY_NUMBER='5' AIRFLOW_CTX_DAG_RUN_ID='scheduled__2024-04-18T01:30:00+00:00'
[2024-04-18T03:45:16.497+0000] {taskinstance.py:430} INFO - ::endgroup::
[2024-04-18T03:45:16.599+0000] {taskinstance.py:441} INFO - ::group::Post task execution logs
[2024-04-18T03:45:16.601+0000] {taskinstance.py:2890} ERROR - Task failed with exception
Traceback (most recent call last):
  File "/home/airflow/.local/lib/python3.12/site-packages/pandas/core/generic.py", line 552, in _get_axis_number
    return cls._AXIS_TO_AXIS_NUMBER[axis]
           ~~~~~~~~~~~~~~~~~~~~~~~~^^^^^^
KeyError: 'state'

During handling of the above exception, another exception occurred:

Traceback (most recent call last):
  File "/home/airflow/.local/lib/python3.12/site-packages/airflow/models/taskinstance.py", line 465, in _execute_task
    result = _execute_callable(context=context, **execute_callable_kwargs)
             ^^^^^^^^^^^^^^^^^^^^^^^^^^^^^^^^^^^^^^^^^^^^^^^^^^^^^^^^^^^^^
  File "/home/airflow/.local/lib/python3.12/site-packages/airflow/models/taskinstance.py", line 432, in _execute_callable
    return execute_callable(context=context, **execute_callable_kwargs)
           ^^^^^^^^^^^^^^^^^^^^^^^^^^^^^^^^^^^^^^^^^^^^^^^^^^^^^^^^^^^^
  File "/home/airflow/.local/lib/python3.12/site-packages/airflow/models/baseoperator.py", line 400, in wrapper
    return func(self, *args, **kwargs)
           ^^^^^^^^^^^^^^^^^^^^^^^^^^^
  File "/home/airflow/.local/lib/python3.12/site-packages/airflow/operators/python.py", line 235, in execute
    return_value = self.execute_callable()
                   ^^^^^^^^^^^^^^^^^^^^^^^
  File "/home/airflow/.local/lib/python3.12/site-packages/airflow/operators/python.py", line 252, in execute_callable
    return self.python_callable(*self.op_args, **self.op_kwargs)
           ^^^^^^^^^^^^^^^^^^^^^^^^^^^^^^^^^^^^^^^^^^^^^^^^^^^^^
  File "/opt/airflow/dags/AggData.py", line 44, in GroupByCountry
    vw_location = df.groupby('country', 'state', 'city').count().reset_index()
                  ^^^^^^^^^^^^^^^^^^^^^^^^^^^^^^^^^^^^^^
  File "/home/airflow/.local/lib/python3.12/site-packages/pandas/core/frame.py", line 8846, in groupby
    axis = self._get_axis_number(axis)
           ^^^^^^^^^^^^^^^^^^^^^^^^^^^
  File "/home/airflow/.local/lib/python3.12/site-packages/pandas/core/generic.py", line 554, in _get_axis_number
    raise ValueError(f"No axis named {axis} for object type {cls.__name__}")
ValueError: No axis named state for object type DataFrame
[2024-04-18T03:45:16.638+0000] {taskinstance.py:1205} INFO - Marking task as FAILED. dag_id=dagAggregation, task_id=vwCountry, execution_date=20240418T013000, start_date=20240418T034516, end_date=20240418T034516
[2024-04-18T03:45:16.661+0000] {standard_task_runner.py:110} ERROR - Failed to execute job 316 for task vwCountry (No axis named state for object type DataFrame; 6397)
[2024-04-18T03:45:16.712+0000] {local_task_job_runner.py:240} INFO - Task exited with return code 1
[2024-04-18T03:45:16.738+0000] {taskinstance.py:3482} INFO - 0 downstream tasks scheduled from follow-on schedule check
[2024-04-18T03:45:16.744+0000] {local_task_job_runner.py:222} INFO - ::endgroup::
