[2024-04-17T02:30:04.132+0000] {local_task_job_runner.py:120} INFO - ::group::Pre task execution logs
[2024-04-17T02:30:04.162+0000] {taskinstance.py:2073} INFO - Dependencies all met for dep_context=non-requeueable deps ti=<TaskInstance: Tutorial_MALUCO.e_valida scheduled__2024-04-17T01:30:00+00:00 [queued]>
[2024-04-17T02:30:04.172+0000] {taskinstance.py:2073} INFO - Dependencies all met for dep_context=requeueable deps ti=<TaskInstance: Tutorial_MALUCO.e_valida scheduled__2024-04-17T01:30:00+00:00 [queued]>
[2024-04-17T02:30:04.174+0000] {taskinstance.py:2303} INFO - Starting attempt 1 of 1
[2024-04-17T02:30:04.194+0000] {taskinstance.py:2327} INFO - Executing <Task(BranchPythonOperator): e_valida> on 2024-04-17 01:30:00+00:00
[2024-04-17T02:30:04.203+0000] {warnings.py:110} WARNING - /home/***/.local/lib/python3.12/site-packages/***/task/task_runner/standard_task_runner.py:61: DeprecationWarning: This process (pid=1791) is multi-threaded, use of fork() may lead to deadlocks in the child.
  pid = os.fork()

[2024-04-17T02:30:04.205+0000] {standard_task_runner.py:63} INFO - Started process 1799 to run task
[2024-04-17T02:30:04.205+0000] {standard_task_runner.py:90} INFO - Running: ['***', 'tasks', 'run', 'Tutorial_MALUCO', 'e_valida', 'scheduled__2024-04-17T01:30:00+00:00', '--job-id', '68', '--raw', '--subdir', 'DAGS_FOLDER/FirstDag.py', '--cfg-path', '/tmp/tmpwxa3ywgs']
[2024-04-17T02:30:04.207+0000] {standard_task_runner.py:91} INFO - Job 68: Subtask e_valida
[2024-04-17T02:30:04.275+0000] {task_command.py:426} INFO - Running <TaskInstance: Tutorial_MALUCO.e_valida scheduled__2024-04-17T01:30:00+00:00 [running]> on host 8dbfbc3d620a
[2024-04-17T02:30:04.391+0000] {taskinstance.py:2644} INFO - Exporting env vars: AIRFLOW_CTX_DAG_OWNER='***' AIRFLOW_CTX_DAG_ID='Tutorial_MALUCO' AIRFLOW_CTX_TASK_ID='e_valida' AIRFLOW_CTX_EXECUTION_DATE='2024-04-17T01:30:00+00:00' AIRFLOW_CTX_TRY_NUMBER='1' AIRFLOW_CTX_DAG_RUN_ID='scheduled__2024-04-17T01:30:00+00:00'
[2024-04-17T02:30:04.393+0000] {taskinstance.py:430} INFO - ::endgroup::
[2024-04-17T02:30:04.393+0000] {baseoperator.py:399} WARNING - BranchPythonOperator.execute cannot be called outside TaskInstance!
[2024-04-17T02:30:04.405+0000] {taskinstance.py:441} INFO - ::group::Post task execution logs
[2024-04-17T02:30:04.406+0000] {taskinstance.py:2890} ERROR - Task failed with exception
Traceback (most recent call last):
  File "/home/airflow/.local/lib/python3.12/site-packages/airflow/models/taskinstance.py", line 465, in _execute_task
    result = _execute_callable(context=context, **execute_callable_kwargs)
             ^^^^^^^^^^^^^^^^^^^^^^^^^^^^^^^^^^^^^^^^^^^^^^^^^^^^^^^^^^^^^
  File "/home/airflow/.local/lib/python3.12/site-packages/airflow/models/taskinstance.py", line 432, in _execute_callable
    return execute_callable(context=context, **execute_callable_kwargs)
           ^^^^^^^^^^^^^^^^^^^^^^^^^^^^^^^^^^^^^^^^^^^^^^^^^^^^^^^^^^^^
  File "/home/airflow/.local/lib/python3.12/site-packages/airflow/models/baseoperator.py", line 400, in wrapper
    return func(self, *args, **kwargs)
           ^^^^^^^^^^^^^^^^^^^^^^^^^^^
  File "/home/airflow/.local/lib/python3.12/site-packages/airflow/operators/python.py", line 269, in execute
    return self.do_branch(context, super().execute(context))
                                   ^^^^^^^^^^^^^^^^^^^^^^^^
  File "/home/airflow/.local/lib/python3.12/site-packages/airflow/models/baseoperator.py", line 400, in wrapper
    return func(self, *args, **kwargs)
           ^^^^^^^^^^^^^^^^^^^^^^^^^^^
  File "/home/airflow/.local/lib/python3.12/site-packages/airflow/operators/python.py", line 235, in execute
    return_value = self.execute_callable()
                   ^^^^^^^^^^^^^^^^^^^^^^^
  File "/home/airflow/.local/lib/python3.12/site-packages/airflow/operators/python.py", line 252, in execute_callable
    return self.python_callable(*self.op_args, **self.op_kwargs)
           ^^^^^^^^^^^^^^^^^^^^^^^^^^^^^^^^^^^^^^^^^^^^^^^^^^^^^
  File "/opt/airflow/dags/FirstDag.py", line 26, in e_valida
    if (qtd > 1):
        ^^^^^^^
TypeError: '>' not supported between instances of 'NoneType' and 'int'
[2024-04-17T02:30:04.422+0000] {taskinstance.py:1205} INFO - Marking task as FAILED. dag_id=Tutorial_MALUCO, task_id=e_valida, execution_date=20240417T013000, start_date=20240417T023004, end_date=20240417T023004
[2024-04-17T02:30:04.441+0000] {standard_task_runner.py:110} ERROR - Failed to execute job 68 for task e_valida ('>' not supported between instances of 'NoneType' and 'int'; 1799)
[2024-04-17T02:30:04.460+0000] {local_task_job_runner.py:240} INFO - Task exited with return code 1
[2024-04-17T02:30:04.484+0000] {taskinstance.py:3482} INFO - 0 downstream tasks scheduled from follow-on schedule check
[2024-04-17T02:30:04.489+0000] {local_task_job_runner.py:222} INFO - ::endgroup::
