[2024-04-18T01:43:59.718+0000] {local_task_job_runner.py:120} INFO - ::group::Pre task execution logs
[2024-04-18T01:43:59.755+0000] {taskinstance.py:2073} INFO - Dependencies all met for dep_context=non-requeueable deps ti=<TaskInstance: dagPartition.transform scheduled__2024-04-18T00:30:00+00:00 [queued]>
[2024-04-18T01:43:59.769+0000] {taskinstance.py:2073} INFO - Dependencies all met for dep_context=requeueable deps ti=<TaskInstance: dagPartition.transform scheduled__2024-04-18T00:30:00+00:00 [queued]>
[2024-04-18T01:43:59.770+0000] {taskinstance.py:2303} INFO - Starting attempt 2 of 2
[2024-04-18T01:43:59.796+0000] {taskinstance.py:2327} INFO - Executing <Task(PythonOperator): transform> on 2024-04-18 00:30:00+00:00
[2024-04-18T01:43:59.804+0000] {warnings.py:110} WARNING - /home/***/.local/lib/python3.12/site-packages/***/task/task_runner/standard_task_runner.py:61: DeprecationWarning: This process (pid=3876) is multi-threaded, use of fork() may lead to deadlocks in the child.
  pid = os.fork()

[2024-04-18T01:43:59.806+0000] {standard_task_runner.py:63} INFO - Started process 3878 to run task
[2024-04-18T01:43:59.807+0000] {standard_task_runner.py:90} INFO - Running: ['***', 'tasks', 'run', 'dagPartition', 'transform', 'scheduled__2024-04-18T00:30:00+00:00', '--job-id', '247', '--raw', '--subdir', 'DAGS_FOLDER/PartitionLocation.py', '--cfg-path', '/tmp/tmpey_z_o_t']
[2024-04-18T01:43:59.808+0000] {standard_task_runner.py:91} INFO - Job 247: Subtask transform
[2024-04-18T01:43:59.881+0000] {task_command.py:426} INFO - Running <TaskInstance: dagPartition.transform scheduled__2024-04-18T00:30:00+00:00 [running]> on host 0761b779d565
[2024-04-18T01:44:00.034+0000] {taskinstance.py:2644} INFO - Exporting env vars: AIRFLOW_CTX_DAG_OWNER='***' AIRFLOW_CTX_DAG_ID='dagPartition' AIRFLOW_CTX_TASK_ID='transform' AIRFLOW_CTX_EXECUTION_DATE='2024-04-18T00:30:00+00:00' AIRFLOW_CTX_TRY_NUMBER='2' AIRFLOW_CTX_DAG_RUN_ID='scheduled__2024-04-18T00:30:00+00:00'
[2024-04-18T01:44:00.035+0000] {taskinstance.py:430} INFO - ::endgroup::
[2024-04-18T01:44:00.146+0000] {taskinstance.py:441} INFO - ::group::Post task execution logs
[2024-04-18T01:44:00.147+0000] {taskinstance.py:2890} ERROR - Task failed with exception
Traceback (most recent call last):
  File "/home/airflow/.local/lib/python3.12/site-packages/pandas/core/indexes/base.py", line 3791, in get_loc
    return self._engine.get_loc(casted_key)
           ^^^^^^^^^^^^^^^^^^^^^^^^^^^^^^^^
  File "index.pyx", line 152, in pandas._libs.index.IndexEngine.get_loc
  File "index.pyx", line 160, in pandas._libs.index.IndexEngine.get_loc
  File "pandas/_libs/index_class_helper.pxi", line 70, in pandas._libs.index.Int64Engine._check_type
KeyError: 'state'

The above exception was the direct cause of the following exception:

Traceback (most recent call last):
  File "/home/airflow/.local/lib/python3.12/site-packages/airflow/models/taskinstance.py", line 465, in _execute_task
    result = _execute_callable(context=context, **execute_callable_kwargs)
             ^^^^^^^^^^^^^^^^^^^^^^^^^^^^^^^^^^^^^^^^^^^^^^^^^^^^^^^^^^^^^
  File "/home/airflow/.local/lib/python3.12/site-packages/airflow/models/taskinstance.py", line 432, in _execute_callable
    return execute_callable(context=context, **execute_callable_kwargs)
           ^^^^^^^^^^^^^^^^^^^^^^^^^^^^^^^^^^^^^^^^^^^^^^^^^^^^^^^^^^^^
  File "/home/airflow/.local/lib/python3.12/site-packages/airflow/models/baseoperator.py", line 400, in wrapper
    return func(self, *args, **kwargs)
           ^^^^^^^^^^^^^^^^^^^^^^^^^^^
  File "/home/airflow/.local/lib/python3.12/site-packages/airflow/operators/python.py", line 235, in execute
    return_value = self.execute_callable()
                   ^^^^^^^^^^^^^^^^^^^^^^^
  File "/home/airflow/.local/lib/python3.12/site-packages/airflow/operators/python.py", line 252, in execute_callable
    return self.python_callable(*self.op_args, **self.op_kwargs)
           ^^^^^^^^^^^^^^^^^^^^^^^^^^^^^^^^^^^^^^^^^^^^^^^^^^^^^
  File "/opt/airflow/dags/PartitionLocation.py", line 48, in TransformationDf
    df = df['state'].str.replace(' ', '_')
         ~~^^^^^^^^^
  File "/home/airflow/.local/lib/python3.12/site-packages/pandas/core/series.py", line 1040, in __getitem__
    return self._get_value(key)
           ^^^^^^^^^^^^^^^^^^^^
  File "/home/airflow/.local/lib/python3.12/site-packages/pandas/core/series.py", line 1156, in _get_value
    loc = self.index.get_loc(label)
          ^^^^^^^^^^^^^^^^^^^^^^^^^
  File "/home/airflow/.local/lib/python3.12/site-packages/pandas/core/indexes/base.py", line 3798, in get_loc
    raise KeyError(key) from err
KeyError: 'state'
[2024-04-18T01:44:00.177+0000] {taskinstance.py:1205} INFO - Marking task as FAILED. dag_id=dagPartition, task_id=transform, execution_date=20240418T003000, start_date=20240418T014359, end_date=20240418T014400
[2024-04-18T01:44:00.204+0000] {standard_task_runner.py:110} ERROR - Failed to execute job 247 for task transform ('state'; 3878)
[2024-04-18T01:44:00.262+0000] {local_task_job_runner.py:240} INFO - Task exited with return code 1
[2024-04-18T01:44:00.306+0000] {taskinstance.py:3482} INFO - 0 downstream tasks scheduled from follow-on schedule check
[2024-04-18T01:44:00.314+0000] {local_task_job_runner.py:222} INFO - ::endgroup::
