[2024-04-18T01:46:45.093+0000] {local_task_job_runner.py:120} INFO - ::group::Pre task execution logs
[2024-04-18T01:46:45.127+0000] {taskinstance.py:2073} INFO - Dependencies all met for dep_context=non-requeueable deps ti=<TaskInstance: dagPartition.transform scheduled__2024-04-18T00:30:00+00:00 [queued]>
[2024-04-18T01:46:45.138+0000] {taskinstance.py:2073} INFO - Dependencies all met for dep_context=requeueable deps ti=<TaskInstance: dagPartition.transform scheduled__2024-04-18T00:30:00+00:00 [queued]>
[2024-04-18T01:46:45.139+0000] {taskinstance.py:2303} INFO - Starting attempt 5 of 5
[2024-04-18T01:46:45.159+0000] {taskinstance.py:2327} INFO - Executing <Task(PythonOperator): transform> on 2024-04-18 00:30:00+00:00
[2024-04-18T01:46:45.168+0000] {warnings.py:110} WARNING - /home/***/.local/lib/python3.12/site-packages/***/task/task_runner/standard_task_runner.py:61: DeprecationWarning: This process (pid=4034) is multi-threaded, use of fork() may lead to deadlocks in the child.
  pid = os.fork()

[2024-04-18T01:46:45.171+0000] {standard_task_runner.py:63} INFO - Started process 4036 to run task
[2024-04-18T01:46:45.173+0000] {standard_task_runner.py:90} INFO - Running: ['***', 'tasks', 'run', 'dagPartition', 'transform', 'scheduled__2024-04-18T00:30:00+00:00', '--job-id', '255', '--raw', '--subdir', 'DAGS_FOLDER/PartitionLocation.py', '--cfg-path', '/tmp/tmpj6cz3oro']
[2024-04-18T01:46:45.176+0000] {standard_task_runner.py:91} INFO - Job 255: Subtask transform
[2024-04-18T01:46:45.247+0000] {task_command.py:426} INFO - Running <TaskInstance: dagPartition.transform scheduled__2024-04-18T00:30:00+00:00 [running]> on host 0761b779d565
[2024-04-18T01:46:45.519+0000] {taskinstance.py:2644} INFO - Exporting env vars: AIRFLOW_CTX_DAG_OWNER='***' AIRFLOW_CTX_DAG_ID='dagPartition' AIRFLOW_CTX_TASK_ID='transform' AIRFLOW_CTX_EXECUTION_DATE='2024-04-18T00:30:00+00:00' AIRFLOW_CTX_TRY_NUMBER='5' AIRFLOW_CTX_DAG_RUN_ID='scheduled__2024-04-18T00:30:00+00:00'
[2024-04-18T01:46:45.521+0000] {taskinstance.py:430} INFO - ::endgroup::
[2024-04-18T01:46:45.615+0000] {python.py:237} INFO - Done. Returned value was: 0     United_States
1     United_States
2     United_States
3     United_States
4     United_States
5     United_States
6     United_States
7     United_States
8     United_States
9     United_States
10    United_States
11    United_States
12    United_States
13    United_States
14    United_States
15    United_States
16    United_States
17    United_States
18    United_States
19          Ireland
20    United_States
21    United_States
22    United_States
23    United_States
24    United_States
25    United_States
26    United_States
27    United_States
28    United_States
29    United_States
30    United_States
31    United_States
32    United_States
33    United_States
34    United_States
35    United_States
36    United_States
37    United_States
38    United_States
39    United_States
40    United_States
41    United_States
42    United_States
43    United_States
44    United_States
45    United_States
46    United_States
47    United_States
48    United_States
49    United_States
Name: country, dtype: object
[2024-04-18T01:46:45.620+0000] {taskinstance.py:441} INFO - ::group::Post task execution logs
[2024-04-18T01:46:45.629+0000] {xcom.py:677} ERROR - Object of type Series is not JSON serializable. If you are using pickle instead of JSON for XCom, then you need to enable pickle support for XCom in your *** config or make sure to decorate your object with attr.
[2024-04-18T01:46:45.631+0000] {taskinstance.py:2890} ERROR - Task failed with exception
Traceback (most recent call last):
  File "/home/airflow/.local/lib/python3.12/site-packages/airflow/utils/json.py", line 91, in default
    return serialize(o)
           ^^^^^^^^^^^^
  File "/home/airflow/.local/lib/python3.12/site-packages/airflow/serialization/serde.py", line 189, in serialize
    raise TypeError(f"cannot serialize object of type {cls}")
TypeError: cannot serialize object of type <class 'pandas.core.series.Series'>

During handling of the above exception, another exception occurred:

Traceback (most recent call last):
  File "/home/airflow/.local/lib/python3.12/site-packages/airflow/models/taskinstance.py", line 486, in _execute_task
    task_instance.xcom_push(key=XCOM_RETURN_KEY, value=xcom_value, session=session)
  File "/home/airflow/.local/lib/python3.12/site-packages/airflow/utils/session.py", line 76, in wrapper
    return func(*args, **kwargs)
           ^^^^^^^^^^^^^^^^^^^^^
  File "/home/airflow/.local/lib/python3.12/site-packages/airflow/models/taskinstance.py", line 3182, in xcom_push
    XCom.set(
  File "/home/airflow/.local/lib/python3.12/site-packages/airflow/utils/session.py", line 76, in wrapper
    return func(*args, **kwargs)
           ^^^^^^^^^^^^^^^^^^^^^
  File "/home/airflow/.local/lib/python3.12/site-packages/airflow/models/xcom.py", line 247, in set
    value = cls.serialize_value(
            ^^^^^^^^^^^^^^^^^^^^
  File "/home/airflow/.local/lib/python3.12/site-packages/airflow/models/xcom.py", line 675, in serialize_value
    return json.dumps(value, cls=XComEncoder).encode("UTF-8")
           ^^^^^^^^^^^^^^^^^^^^^^^^^^^^^^^^^^
  File "/usr/local/lib/python3.12/json/__init__.py", line 238, in dumps
    **kw).encode(obj)
          ^^^^^^^^^^^
  File "/home/airflow/.local/lib/python3.12/site-packages/airflow/utils/json.py", line 104, in encode
    return super().encode(o)
           ^^^^^^^^^^^^^^^^^
  File "/usr/local/lib/python3.12/json/encoder.py", line 200, in encode
    chunks = self.iterencode(o, _one_shot=True)
             ^^^^^^^^^^^^^^^^^^^^^^^^^^^^^^^^^^
  File "/usr/local/lib/python3.12/json/encoder.py", line 258, in iterencode
    return _iterencode(o, 0)
           ^^^^^^^^^^^^^^^^^
  File "/home/airflow/.local/lib/python3.12/site-packages/airflow/utils/json.py", line 93, in default
    return super().default(o)
           ^^^^^^^^^^^^^^^^^^
  File "/usr/local/lib/python3.12/json/encoder.py", line 180, in default
    raise TypeError(f'Object of type {o.__class__.__name__} '
TypeError: Object of type Series is not JSON serializable
[2024-04-18T01:46:45.644+0000] {taskinstance.py:1205} INFO - Marking task as FAILED. dag_id=dagPartition, task_id=transform, execution_date=20240418T003000, start_date=20240418T014645, end_date=20240418T014645
[2024-04-18T01:46:45.666+0000] {standard_task_runner.py:110} ERROR - Failed to execute job 255 for task transform (Object of type Series is not JSON serializable; 4036)
[2024-04-18T01:46:45.708+0000] {local_task_job_runner.py:240} INFO - Task exited with return code 1
[2024-04-18T01:46:45.745+0000] {taskinstance.py:3482} INFO - 0 downstream tasks scheduled from follow-on schedule check
[2024-04-18T01:46:45.753+0000] {local_task_job_runner.py:222} INFO - ::endgroup::
