[2024-04-18T05:01:28.145+0000] {local_task_job_runner.py:120} INFO - ::group::Pre task execution logs
[2024-04-18T05:01:28.180+0000] {taskinstance.py:2073} INFO - Dependencies all met for dep_context=non-requeueable deps ti=<TaskInstance: dagPartition.input scheduled__2024-04-18T02:30:00+00:00 [queued]>
[2024-04-18T05:01:28.193+0000] {taskinstance.py:2073} INFO - Dependencies all met for dep_context=requeueable deps ti=<TaskInstance: dagPartition.input scheduled__2024-04-18T02:30:00+00:00 [queued]>
[2024-04-18T05:01:28.194+0000] {taskinstance.py:2303} INFO - Starting attempt 2 of 2
[2024-04-18T05:01:28.215+0000] {taskinstance.py:2327} INFO - Executing <Task(PythonOperator): input> on 2024-04-18 02:30:00+00:00
[2024-04-18T05:01:28.224+0000] {warnings.py:110} WARNING - /home/***/.local/lib/python3.12/site-packages/***/task/task_runner/standard_task_runner.py:61: DeprecationWarning: This process (pid=7666) is multi-threaded, use of fork() may lead to deadlocks in the child.
  pid = os.fork()

[2024-04-18T05:01:28.226+0000] {standard_task_runner.py:63} INFO - Started process 7668 to run task
[2024-04-18T05:01:28.226+0000] {standard_task_runner.py:90} INFO - Running: ['***', 'tasks', 'run', 'dagPartition', 'input', 'scheduled__2024-04-18T02:30:00+00:00', '--job-id', '335', '--raw', '--subdir', 'DAGS_FOLDER/PartitionLocation.py', '--cfg-path', '/tmp/tmp06201rwh']
[2024-04-18T05:01:28.227+0000] {standard_task_runner.py:91} INFO - Job 335: Subtask input
[2024-04-18T05:01:28.296+0000] {task_command.py:426} INFO - Running <TaskInstance: dagPartition.input scheduled__2024-04-18T02:30:00+00:00 [running]> on host 0761b779d565
[2024-04-18T05:01:28.470+0000] {taskinstance.py:2644} INFO - Exporting env vars: AIRFLOW_CTX_DAG_OWNER='***' AIRFLOW_CTX_DAG_ID='dagPartition' AIRFLOW_CTX_TASK_ID='input' AIRFLOW_CTX_EXECUTION_DATE='2024-04-18T02:30:00+00:00' AIRFLOW_CTX_TRY_NUMBER='2' AIRFLOW_CTX_DAG_RUN_ID='scheduled__2024-04-18T02:30:00+00:00'
[2024-04-18T05:01:28.472+0000] {taskinstance.py:430} INFO - ::endgroup::
[2024-04-18T05:01:28.474+0000] {taskinstance.py:441} INFO - ::group::Post task execution logs
[2024-04-18T05:01:28.475+0000] {taskinstance.py:2890} ERROR - Task failed with exception
Traceback (most recent call last):
  File "/home/airflow/.local/lib/python3.12/site-packages/airflow/models/taskinstance.py", line 465, in _execute_task
    result = _execute_callable(context=context, **execute_callable_kwargs)
             ^^^^^^^^^^^^^^^^^^^^^^^^^^^^^^^^^^^^^^^^^^^^^^^^^^^^^^^^^^^^^
  File "/home/airflow/.local/lib/python3.12/site-packages/airflow/models/taskinstance.py", line 432, in _execute_callable
    return execute_callable(context=context, **execute_callable_kwargs)
           ^^^^^^^^^^^^^^^^^^^^^^^^^^^^^^^^^^^^^^^^^^^^^^^^^^^^^^^^^^^^
  File "/home/airflow/.local/lib/python3.12/site-packages/airflow/models/baseoperator.py", line 400, in wrapper
    return func(self, *args, **kwargs)
           ^^^^^^^^^^^^^^^^^^^^^^^^^^^
  File "/home/airflow/.local/lib/python3.12/site-packages/airflow/operators/python.py", line 235, in execute
    return_value = self.execute_callable()
                   ^^^^^^^^^^^^^^^^^^^^^^^
  File "/home/airflow/.local/lib/python3.12/site-packages/airflow/operators/python.py", line 252, in execute_callable
    return self.python_callable(*self.op_args, **self.op_kwargs)
           ^^^^^^^^^^^^^^^^^^^^^^^^^^^^^^^^^^^^^^^^^^^^^^^^^^^^^
  File "/opt/airflow/dags/PartitionLocation.py", line 46, in ReadBronze
    df = pd.read_json(f'datalake/bronze/{format_dt}.json', dtype=schema)
         ^^^^^^^^^^^^^^^^^^^^^^^^^^^^^^^^^^^^^^^^^^^^^^^^^^^^^^^^^^^^^^^
  File "/home/airflow/.local/lib/python3.12/site-packages/pandas/io/json/_json.py", line 780, in read_json
    json_reader = JsonReader(
                  ^^^^^^^^^^^
  File "/home/airflow/.local/lib/python3.12/site-packages/pandas/io/json/_json.py", line 893, in __init__
    data = self._get_data_from_filepath(filepath_or_buffer)
           ^^^^^^^^^^^^^^^^^^^^^^^^^^^^^^^^^^^^^^^^^^^^^^^^
  File "/home/airflow/.local/lib/python3.12/site-packages/pandas/io/json/_json.py", line 949, in _get_data_from_filepath
    raise FileNotFoundError(f"File {filepath_or_buffer} does not exist")
FileNotFoundError: File datalake/bronze/20240418.json does not exist
[2024-04-18T05:01:28.489+0000] {taskinstance.py:1205} INFO - Marking task as FAILED. dag_id=dagPartition, task_id=input, execution_date=20240418T023000, start_date=20240418T050128, end_date=20240418T050128
[2024-04-18T05:01:28.558+0000] {standard_task_runner.py:110} ERROR - Failed to execute job 335 for task input (File datalake/bronze/20240418.json does not exist; 7668)
[2024-04-18T05:01:28.601+0000] {local_task_job_runner.py:240} INFO - Task exited with return code 1
[2024-04-18T05:01:28.642+0000] {taskinstance.py:3482} INFO - 0 downstream tasks scheduled from follow-on schedule check
[2024-04-18T05:01:28.650+0000] {local_task_job_runner.py:222} INFO - ::endgroup::
