[2024-04-18T01:43:21.291+0000] {local_task_job_runner.py:120} INFO - ::group::Pre task execution logs
[2024-04-18T01:43:21.316+0000] {taskinstance.py:2073} INFO - Dependencies all met for dep_context=non-requeueable deps ti=<TaskInstance: dagPartition.transform manual__2024-04-18T01:14:39.903288+00:00 [queued]>
[2024-04-18T01:43:21.326+0000] {taskinstance.py:2073} INFO - Dependencies all met for dep_context=requeueable deps ti=<TaskInstance: dagPartition.transform manual__2024-04-18T01:14:39.903288+00:00 [queued]>
[2024-04-18T01:43:21.327+0000] {taskinstance.py:2303} INFO - Starting attempt 16 of 16
[2024-04-18T01:43:21.348+0000] {taskinstance.py:2327} INFO - Executing <Task(PythonOperator): transform> on 2024-04-18 01:14:39.903288+00:00
[2024-04-18T01:43:21.355+0000] {warnings.py:110} WARNING - /home/***/.local/lib/python3.12/site-packages/***/task/task_runner/standard_task_runner.py:61: DeprecationWarning: This process (pid=3823) is multi-threaded, use of fork() may lead to deadlocks in the child.
  pid = os.fork()

[2024-04-18T01:43:21.357+0000] {standard_task_runner.py:63} INFO - Started process 3825 to run task
[2024-04-18T01:43:21.362+0000] {standard_task_runner.py:90} INFO - Running: ['***', 'tasks', 'run', 'dagPartition', 'transform', 'manual__2024-04-18T01:14:39.903288+00:00', '--job-id', '243', '--raw', '--subdir', 'DAGS_FOLDER/PartitionLocation.py', '--cfg-path', '/tmp/tmp8flhplob']
[2024-04-18T01:43:21.365+0000] {standard_task_runner.py:91} INFO - Job 243: Subtask transform
[2024-04-18T01:43:21.434+0000] {task_command.py:426} INFO - Running <TaskInstance: dagPartition.transform manual__2024-04-18T01:14:39.903288+00:00 [running]> on host 0761b779d565
[2024-04-18T01:43:21.586+0000] {taskinstance.py:2644} INFO - Exporting env vars: AIRFLOW_CTX_DAG_OWNER='***' AIRFLOW_CTX_DAG_ID='dagPartition' AIRFLOW_CTX_TASK_ID='transform' AIRFLOW_CTX_EXECUTION_DATE='2024-04-18T01:14:39.903288+00:00' AIRFLOW_CTX_TRY_NUMBER='16' AIRFLOW_CTX_DAG_RUN_ID='manual__2024-04-18T01:14:39.903288+00:00'
[2024-04-18T01:43:21.589+0000] {taskinstance.py:430} INFO - ::endgroup::
[2024-04-18T01:43:21.687+0000] {taskinstance.py:441} INFO - ::group::Post task execution logs
[2024-04-18T01:43:21.688+0000] {taskinstance.py:2890} ERROR - Task failed with exception
Traceback (most recent call last):
  File "/home/airflow/.local/lib/python3.12/site-packages/pandas/core/indexes/base.py", line 3791, in get_loc
    return self._engine.get_loc(casted_key)
           ^^^^^^^^^^^^^^^^^^^^^^^^^^^^^^^^
  File "index.pyx", line 152, in pandas._libs.index.IndexEngine.get_loc
  File "index.pyx", line 160, in pandas._libs.index.IndexEngine.get_loc
  File "pandas/_libs/index_class_helper.pxi", line 70, in pandas._libs.index.Int64Engine._check_type
KeyError: 'state'

The above exception was the direct cause of the following exception:

Traceback (most recent call last):
  File "/home/airflow/.local/lib/python3.12/site-packages/airflow/models/taskinstance.py", line 465, in _execute_task
    result = _execute_callable(context=context, **execute_callable_kwargs)
             ^^^^^^^^^^^^^^^^^^^^^^^^^^^^^^^^^^^^^^^^^^^^^^^^^^^^^^^^^^^^^
  File "/home/airflow/.local/lib/python3.12/site-packages/airflow/models/taskinstance.py", line 432, in _execute_callable
    return execute_callable(context=context, **execute_callable_kwargs)
           ^^^^^^^^^^^^^^^^^^^^^^^^^^^^^^^^^^^^^^^^^^^^^^^^^^^^^^^^^^^^
  File "/home/airflow/.local/lib/python3.12/site-packages/airflow/models/baseoperator.py", line 400, in wrapper
    return func(self, *args, **kwargs)
           ^^^^^^^^^^^^^^^^^^^^^^^^^^^
  File "/home/airflow/.local/lib/python3.12/site-packages/airflow/operators/python.py", line 235, in execute
    return_value = self.execute_callable()
                   ^^^^^^^^^^^^^^^^^^^^^^^
  File "/home/airflow/.local/lib/python3.12/site-packages/airflow/operators/python.py", line 252, in execute_callable
    return self.python_callable(*self.op_args, **self.op_kwargs)
           ^^^^^^^^^^^^^^^^^^^^^^^^^^^^^^^^^^^^^^^^^^^^^^^^^^^^^
  File "/opt/airflow/dags/PartitionLocation.py", line 48, in TransformationDf
    df = df['state'].str.replace(' ', '_')
         ~~^^^^^^^^^
  File "/home/airflow/.local/lib/python3.12/site-packages/pandas/core/series.py", line 1040, in __getitem__
    return self._get_value(key)
           ^^^^^^^^^^^^^^^^^^^^
  File "/home/airflow/.local/lib/python3.12/site-packages/pandas/core/series.py", line 1156, in _get_value
    loc = self.index.get_loc(label)
          ^^^^^^^^^^^^^^^^^^^^^^^^^
  File "/home/airflow/.local/lib/python3.12/site-packages/pandas/core/indexes/base.py", line 3798, in get_loc
    raise KeyError(key) from err
KeyError: 'state'
[2024-04-18T01:43:21.711+0000] {taskinstance.py:1205} INFO - Marking task as FAILED. dag_id=dagPartition, task_id=transform, execution_date=20240418T011439, start_date=20240418T014321, end_date=20240418T014321
[2024-04-18T01:43:21.728+0000] {standard_task_runner.py:110} ERROR - Failed to execute job 243 for task transform ('state'; 3825)
[2024-04-18T01:43:21.773+0000] {local_task_job_runner.py:240} INFO - Task exited with return code 1
[2024-04-18T01:43:21.814+0000] {taskinstance.py:3482} INFO - 0 downstream tasks scheduled from follow-on schedule check
[2024-04-18T01:43:21.823+0000] {local_task_job_runner.py:222} INFO - ::endgroup::
